Workbook
Name add_5: #REF!
Name Adv_Strategic_Pillars: #REF!
Name Advantages: #REF!
Name Alignment_With_Key_Nike_Objectives__Next_Strategic_Pillars: #REF!
Name Alignment_With_Key_Nike_Objectives_Next__Strategic_Pillars: #REF!
Name Alignment_With_Next__Strategic_Pillars: #REF!
Name AlignmentWithNext_StrategicPillars: #REF!
Name Capital_Expenditure: #REF!
Name Capital_Expenditures: #REF!
Name Cost_of_Goods_Sold: #REF!
Name Costs: 'Costs_L1 Drop Down'!$A$2:$A$6
Name Date: #REF!
Name Direct: #REF!
Name Direct___Indirect: #REF!
Name Engagement: #REF!
Name Expenses: #REF!
Name Increase_in_Average_Transaction_Value: #REF!
Name Increase_in_Conversion: #REF!
Name Increase_in_Foot_Traffic: #REF!
Name Interest: #REF!
Name Name: #REF!
Name number: #REF!
Name Operating_Expenses: #REF!
Name Revenue: 'Rev_L1 Drop Down'!$A$2:$A$4
Name Revenue_Uplift: #REF!
Name Risks: #REF!
Name Scenario_Toggle: 'Scenario Planning_Drop Down'!$A$2:$A$4
Name Scenario_Toggles: 'Scenario Planning_Drop Down'!$A$2:$A$4
Name Strategic_Pillars: #REF!
Name Sub_Levers: #REF!
Name Taxes: #REF!
Name Timeline: #REF!
Name Transition: #REF!
Name Transition_Scaling: #REF!

Sheet 0. Overview & Table of Contents
D2: Liberata: Market Sizing and Financial Projections
D4: 1. Table of Contents breaks down how the Excel file is laid out
C11: 1. Table of Contents:
C13: Section | D13: Index | E13: Description
C14: Instructions & Definitions | D14: 1 | E14: Instructions for how to view and navigate the file in addition to explaining how to adjust inputs and assumptions.
C15: Control Panel | D15: 2 | E15: Provides inputs and assumptions used across the market sizing and financial projections, which can be modified and adjusted, per 1. Instructions & Definitions
C16: Market Sizing Summary | D16: 3 | E16: Provides a high level overview of Total Addressable Market, Serviceable Addressable Market, and Serviceable Obtainable Market across relevant sectors
C17: Market Sizing Calculations | D17: 3.1 | E17: Provides details on methodologies and calculations for market sizing across sectors
C18: Revenue Model Summary | D18: 4 | E18: Provides a high level overview of revenue and cost projections for years 1-10
C19: Revenue & Cost Breakdown | D19: 4.1 | E19: Provides a deeper breakdown of estimates YoY of revenues and costs
C22: 45962

Sheet 1. Instructions & Definitions
D2: Market Sizing and Finanical Projections: Instructions & Definitions
D4: 1. To View & Navigate the File The order in which the viewer should click through the file
D5: 2. To Adjust Inputs and Assumptions Description on how the viewer can adjust the numbers/figures
D6: 3. Important Definitions/Descriptions Explanations on the meaning/importance of various terms/figures used throughout the file
C11: 1.To View & Navigate the File:
C12: 1. After reviewing 1.0 Overview & Table of Contents, review this sheet to understand how to navigate the file
C13: 2. To adjust inputs to both the market sizing and financial projections, proceed to 2. Control Panel to make adjustments to assumptions
C14: 2. Proceed to 3. Market Sizing Summary and 4. Financial Projection Summary to see the high-level overview on the modeling for Liberata
C15: 3. Continue to 3.1 Market Sizing Breakdown to understand specific methodologies used to calculate TAM, SAM, and SOM across relevant markets
C16: 4. Proceed to the 4.1 Revenue & Cost Breakdown to understand initial revenue and cost projections for years 1-10
C18: 2. To Adjust Inputs and Assumptions:
C19: 1. Whenever a blue box saying "Dropdown adjustment" appears, click on the dropdown and choose one of the values to affect the outputs of the sheet
C20: 2. General Rule of Thumb: All numbers in blue in Control Panel are assumptions that can be changed as deemed fit - without breaking the model
C22: 3. Important Definitions/Descriptions:
C23: Word/Value | D23: Sections Included | E23: Definition
C24: Low | D24: 4.0 Financial Projection Summary | E24: Provides a rough sensitivity analysis on revenues and costs, providing a range for expectations
C25: Moderate
C26: High
C27: R1/R2/R3 University | D27: 2.0 Control Panel, 4.1 Revenue & Cost Breakdown | E27: The Carnegie Classification system categorizes U.S. universities based on research activity, degree offerings, and institutional characteristics—such as R1 (very high research), R2 (high research), and R3 (moderate research)—while non-doctoral U.S. universities and global institutions not covered by this framework are classified separately
C28: Non-Doctoral U.S. University
C29: Other Global Universities
C30: Phase 1 - Seed Development | D30: 4.1 Revenue & Cost Breakdown | E30: Phase 1 – Seed Development: Build and launch the core metrics platform with a small team; Phase 2 – Growth: scale the product, marketing, and grow/consider additional AI capabilities; Phase 3 – Expansion: mature operations, expand globally
C31: Phase 2 - Growth
C32: Phase 3 - Expansion

Sheet 2. Control Panel
D2: Market Sizing and Financial Projections: Control Panel
D4: 1. Control Panel 1 Provides inputs and adjustable assumptions included in the market sizing
D5: 2. Control Panel 2 Provides inputs and adjustable assumptions included in the revenue and cost model
C9: Control Panel 1: Market Sizing | I9: Control Panel 2: Financial Projetions
E10: Modify/adjust figures in bolded blue | L10: Modify/adjust figures in bolded blue
C11: Category | D11: Metric Description | E11: Figure | F11: Used in the market sizing? Y/N | G11: Source | I11: Category | J11: User | K11: Metric Description | L11: Figure | M11: Explanation/Justification/Source | O11: SCENARIO 3--- Cost
C12: Academic Publishing | D12: $ size of the entire global academic publishing market | E12: 25600000000 | F12: Yes | G12: https://marketintelo.com/report/academic-publishing-market | I12: Revenue | J12: General - revenues | K12: % growth YoY in users (all users except universities) | L12: 0.1 | M12: ASSUMPTON | O12: Reduces cost growth to test whether improved operational efficiency can enhance profitability and achieve earlier breakeven without increasing revenue.
D13: entire academic publishing global growht rate CAGR | E13: 0.046 | F13: No | G13: https://marketintelo.com/report/academic-publishing-market | K13: % growth YoY in price (i.e.., user spend for non-universities) on subscription in years 1-3 | L13: 0 | M13: ASSUMPTION
D14: % of the academic journal market Liberata can capture | E14: 0.3 | F14: Yes | G14: ASSUMPTION - capturing half of the market that the top 5 journals currently have (which is around 60%) | K14: % growth YoY in price (i.e.., user spend for non-universities) on subscription in years 4-10 | L14: 0.05 | M14: ASSUMPTION
D15: % of the academic publishing market that the top 5 journals make up (El Selvier, Springer Nature, Wiley, Taylor & Francis, Sage) | E15: =0.16+0.15+0.13+0.1+0.06 -> 0.6 | F15: No | G15: https://www.linkedin.com/pulse/hidden-fortune-academic-publishers-closer-look-industrys-kannan-cmxac/ | K15: Sensitivity analysis - Low projections scenario | L15: 0.75 | M15: ASSUMPTION
D16: Percent of journal revenues coming from corporate subscriptions | E16: 0.17 | F16: Yes | G16: https://firstmonday.org/ojs/index.php/fm/article/view/4370/3685 | K16: Sensitivity analysis - Moderate projections scenario | L16: 1 | M16: ASSUMPTION
D17: Percent of journal revenues coming from advertising | E17: 0.04 | F17: Yes | G17: https://firstmonday.org/ojs/index.php/fm/article/view/4370/3685 | K17: Sensitivity analysis - High projections scenario | L17: 1.25 | M17: ASSUMPTION
D18: Percent of journal revenues coming from membership and personal subscriptions | E18: 0.03 | F18: Yes | G18: https://firstmonday.org/ojs/index.php/fm/article/view/4370/3685 | J18: Universities | K18: Number of universities in year 1 with a Liberata subscription | L18: 15 | M18: ASSUMPTION - requires convincing a reasonable amount to try Liberata on free trial
D19: Percent of journal revenues coming from author side payments | E19: 0.03 | F19: Yes | G19: https://firstmonday.org/ojs/index.php/fm/article/view/4370/3685 | K19: % of universities in years 1 and 2 with a free trial Liberata subscription | L19: 1 | M19: ASSUMPTION - requires convincing a reasonable amount to try Liberata on free trial
D20: Percent of journal revenues coming from university library subscriptions | E20: 0.73 | F20: Yes | G20: https://firstmonday.org/ojs/index.php/fm/article/view/4370/3685 | K20: % of universities in years 3 and beyond with a free trial Liberata subscription | L20: 0 | M20: ASSUMPTION - requires convincing a reasonable amount to try Liberata on free trial
C21: Academic metrics | D21: Average annual spend for academic metrics/bibliometrics per university - R1 | E21: =40000 -> 40000 | F21: Yes | G21: ASSUMPTION - based on Han's insights about the cost of Clarivate and SCOPUS | K21: % growth YoY in universities with a Liberata subscription - year 2 | L21: 1 | M21: ASSUMPTION - Network effects will occur as more users join
D22: Average annual spend on academic metrics/bibliometrics per university - R2 | E22: =0.4*E21 -> 16000 | F22: Yes | G22: ASSUMPTION - take 40% of R1 spend | K22: % growth YoY in universities with a Liberata subscription - years 3-5 | L22: 0.5 | M22: ASSUMPTION - May be more challenging to secure many universities once payment is required and free trials end
D23: Average annual spend on academic metrics/bibliometrics per university - R3 | E23: =0.2*E21 -> 8000 | F23: Yes | G23: ASSUMPTION - take 20% of R1 spend | K23: % growth YoY in universities with a Liberata subscription - years 6-8 | L23: 0.6 | M23: ASSUMPTION - Network effects will occur as more users join
D24: Average annual spend for academic metrics/bibliometrics per university - other | E24: =0.05*E21 -> 2000 | F24: Yes | G24: ASSUMPTION - take 5% of R1 spend | K24: % growth YoY in universities with a Liberata subscription - years 9-10 | L24: 0.5 | M24: ASSUMPTION - Growth will slow as the capturable universities are reached
D25: Average annual spend for academic metrics/bibliometrics per university - global | E25: =0.05*E21 -> 2000 | F25: Yes | G25: ASSUMPTION - take 5% of R1 spend | K25: Price of bundle offered to universities - free trial period | L25: 0 | M25: Free trials for universities to show value of the platform
D26: % of universities paying for academic metrics/bibliometrics - R1 | E26: 0.95 | F26: Yes | G26: ASSUMPTION | K26: Starting price - R1 universities | L26: 200000 | M26: Must price Liberata much less than current journal subscription amounts
D27: % of universities paying for academic metrics/bibliometrics - R2 | E27: 0.8 | F27: Yes | G27: ASSUMPTION | K27: Starting price - R2 universities | L27: =0.9*L26 -> 180000 | M27: R2 university price is 90% of R1 university price
D28: % of universities paying for academic metrics/bibliometrics - R3 | E28: 0.6 | F28: Yes | G28: ASSUMPTION | K28: Starting price - R3 universities | L28: =0.8*L26 -> 160000 | M28: R3 university price is 80% of R1 university price
D29: % of universities paying for academic metrics/bibliometrics - other | E29: 0.5 | F29: Yes | G29: ASSUMPTION | K29: Starting price - non-doctoral U.S. universities | L29: =0.7*L26 -> 140000 | M29: Other U.S. university prices are 70% of R1 university price
D30: % of universities paying for academic metrics/bibliometrics - global | E30: 0.2 | F30: Yes | G30: ASSUMPTION | K30: Starting price - other global universities | L30: =0.6*L26 -> 120000 | M30: Other global university prices are 60% of R1 university price
D31: total # R1 research universities | E31: 187 | F31: Yes | G31: https://carnegieclassifications.acenet.edu/institutions/?inst=&research2025%5B%5D=1 | K31: % growth YoY in price for universities (i.e., university spend) years 1-3 | L31: 0 | M31: Liberata needs to gain market share and show value before increasing prices
D32: total # R2 research universities | E32: 139 | F32: Yes | G32: https://carnegieclassifications.acenet.edu/institutions/?inst=&research2025%5B%5D=2 | K32: % growth YoY in price for universities (i.e., university spend) years 4-10 | L32: 0.05 | M32: Universities will be willing to pay more for Liberata as its value is shown and as network effects occur
D33: total # R3 research universities | E33: 189 | F33: Yes | G33: https://robertkelchen.com/2021/12/16/how-colleges-carnegie-classifications-have-changed-over-time-2/#:~:text=Every%20three%20years%2C%20Indiana%20University's%20Center%20on,doesn't%20hesitate%20to%20share%20their%20opinions%20about | K33: total # R1 research universities | L33: =E31 -> 187 | M33: [DO NOT CHANGE HERE - CHANGE IN MARKET SIZING PANEL]
D34: total # other research producing universities in the US | E34: =E42-SUM(E31:E33) -> 555 | F34: Yes | G34: CALCULATION | K34: total # R2 research universities | L34: =E32 -> 139 | M34: [DO NOT CHANGE HERE - CHANGE IN MARKET SIZING PANEL]
D35: total # other research universities globally | E35: =E45-SUM(E31:E34) -> 5788.9744 | F35: Yes | G35: CALCULATION | K35: total # R3 research universities | L35: =E33 -> 189 | M35: [DO NOT CHANGE HERE - CHANGE IN MARKET SIZING PANEL]
D36: academic metrics growth rate | E36: Unknown | F36: No | K36: total # other research producing universities in the US | L36: =E34 -> 555 | M36: [DO NOT CHANGE HERE - CHANGE IN MARKET SIZING PANEL]
C37: AI Licensing for academic publishing | D37: AI Licensing for Academic Publishing | E37: 381800000 | F37: Yes | G37: https://www.grandviewresearch.com/industry-analysis/ai-datasets-licensing-academic-research-publishing-market-report | K37: total # other research universities globally | L37: =E35 -> 5788.9744 | M37: [DO NOT CHANGE HERE - CHANGE IN MARKET SIZING PANEL]
D38: AI Licensing for Academic Publishing growth rate CAGR | E38: 0.268 | F38: No | G38: https://www.grandviewresearch.com/industry-analysis/ai-datasets-licensing-academic-research-publishing-market-report | J38: Think Tanks/Non-profits | K38: Number of think tanks/non-profits in years 1-5 with a Liberata subscription | L38: 0 | M38: ASSUMPTION - conservative estimation that the focus of BD efforts will be on universities for the first five years
D39: AI Training Dataset Share of entire AI licensing market | E39: 0.324 | F39: Yes | G39: https://www.grandviewresearch.com/industry-analysis/ai-datasets-licensing-academic-research-publishing-market-report | K39: Number of think tanks/non-profits in year 6 with a Liberata subscription | L39: 3000 | M39: ASSUMPTION - there are around 2 million non profits in the US
D40: North america share of revenue for AI licensing market | E40: 0.394 | F40: No | G40: https://www.grandviewresearch.com/industry-analysis/ai-datasets-licensing-academic-research-publishing-market-report | K40: Cost of bundle offered to think tanks/non-profits | L40: 50000 | M40: ASSUMPTION
D41: % of the market Liberata can capture | E41: 0.1 | F41: Yes | G41: ASSUMPTION | J41: Government Organizations | K41: Number of government orgs in years 1-5 with a Liberata subscription | L41: 0 | M41: ASSUMPTION - conservative estimation that the focus of BD efforts will be on universities for the first five years
C42: General | D42: # of research producing instutitions - US based | E42: =115+104+109+742 -> 1070 | F42: Yes | G42: https://nces.ed.gov/programs/digest/d18/tables/dt18_317.40.asp | K42: Number of government orgs in year 6 with a Liberata subscription | L42: 500 | M42: ASSUMPTION
D43: United states share of research publications in 2020 | E43: 0.156 | F43: Yes | G43: https://research-and-innovation.ec.europa.eu/system/files/2022-07/ec_rtd_srip-2022-report-chapter-6.pdf#:~:text=Figure%206.1%2D1:%20World%20share%20of%20scientific%20publications(1)%2C,(2)BRIS:%20Brazil%2C%20Russia%2C%20India%20and%20South%20Africa. | K43: Cost of bundle offered to government organizations | L43: 50000 | M43: ASSUMPTION
D44: # of research producing instutitions - Non-US | E44: =(E42/E43)*(1-E43) -> 5788.9744 | F44: Yes | G44: CALCULATION | J44: Corporations | K44: Number of corporations in years 1-5 with a Liberata subscription | L44: 0 | M44: ASSUMPTION - conservative estimation that the focus of BD efforts will be on universities for the first five years
D45: # of research producing instutitions - Globally | E45: =E42+E44 -> 6858.9744 | F45: Yes | G45: CALCULATION | K45: Number of corporations in year 6 with a Liberata subscription | L45: 500 | M45: ASSUMPTION
...

Sheet 3. Market Sizing Summary
D2: Market Sizing Summary
D4: 1. Market Sizing Summary Summarized findings from 3.1 Market Sizing Breakdown
C9: Market Sizing Summary
C11: Market | D11: Industry Growth Rate (CAGR) | E11: TAM | F11: SAM | G11: SOM
C12: Academic Publishing | D12: ='2. Control Panel'!E13 -> 0.046 | E12: ='3.1 Market Sizing Breakdown'!E16 -> 25600000000 | F12: ='3.1 Market Sizing Breakdown'!E17 -> 24832000000 | G12: ='3.1 Market Sizing Breakdown'!E18 -> 7449600000
C13: Academic Metrics | D13: ='2. Control Panel'!E36 -> Unknown | E13: ='3.1 Market Sizing Breakdown'!G25 -> 12662990 | F13: ='3.1 Market Sizing Breakdown'!G30 -> 12662990 | G13: ='3.1 Market Sizing Breakdown'!G31 -> 12662990
C14: AI Licensing | D14: ='2. Control Panel'!E38 -> 0.268 | E14: ='3.1 Market Sizing Breakdown'!E38 -> 381800000 | F14: ='3.1 Market Sizing Breakdown'!E39 -> 123703200 | G14: ='3.1 Market Sizing Breakdown'!E40 -> 12370320
C15: TOTALS | E15: =SUM(E12:E14) -> 2.5994463e+10 | F15: =SUM(F12:F14) -> 2.4968366e+10 | G15: =SUM(G12:G14) -> 7.4746333e+09
C17: Note: Although not used in market sizing calculations, the industry CAGR for academic/educational software is 8.8%

Sheet 3.1 Market Sizing Breakdown
D2: Market Sizing Breakdown
D4: 1. Assumptions Details key decision points affecting the model
D5: 2. Market Sizing by Sector Breaks down market sizing for three relevant sectors
C8: Assumptions
B9: 1 | C9: Universities conducting more research are 1) spending more and 2) more likely to spend money on academic metrics
B10: 2 | C10: Liberata's patent and ability to maintain superior metrics enables it to capture the entire academic metrics market
B11: 3 | C11: Liberata will be able to capture roughly a tenth of the AI licensing for academic publishing market
C13: 1. Academic Publishing
C15: Level | D15: Method Description | E15: Total Figure
C16: Total Addressable Market (TAM) | D16: Based on global market size estimates from Market Intelo covering the broader academic publishing | E16: ='2. Control Panel'!E12 -> 25600000000
C17: Serviceable Addressable Market (SAM) | D17: Narrows this down to the segments Liberata can realistically target—subscriptions from university libraries, corporations, and individual users in addition to advertising—while excluding author-side APC article processing payments that don’t fit Liberata’s model Method: TAM x relevant category percentages (e.g., subscriptions but NOT article processing charges) | E17: ='2. Control Panel'!E12*('2. Control Panel'!E16+'2. Control Panel'!E17+'2. Control Panel'!E18+'2. Control Panel'!E20) -> 24832000000
C18: Serviceable Obtainable Market (SOM) | D18: Reflects an assumed percentage of the market that Liberata can realistically capture as the industry gradually shifts from view-based to metric-based incentives, recognizing that part of the market will likely stay tied to legacy journal systems | E18: =E17*'2. Control Panel'!E14 -> 7449600000
C22: 2. Academic Metrics
C24: Level | D24: Method Description | E24: Breakdown of categories | F24: Broken down figure | G24: Total Figure
C25: Total Addressable Market (TAM) | D25: Calculated by multiplying the number of research-producing institutions globally—broken down by Carnegie Classifiers (R1, R2, R3, and other U.S. or international equivalents)—by their estimated annual spend on academic metrics, then adjusting for each group’s likelihood of paying for such tools Method: Number of each type of university x spend based on the type of university x percentage likelihood of each type of university to spend on academic metrics | E25: R1 University | F25: ='2. Control Panel'!E21*'2. Control Panel'!E26*'2. Control Panel'!E31 -> 7106000 | G25: =SUM(F25:F29) -> 12662990
E26: R2 University | F26: ='2. Control Panel'!E22*'2. Control Panel'!E27*'2. Control Panel'!E32 -> 1779200
E27: R3 University | F27: ='2. Control Panel'!E23*'2. Control Panel'!E28*'2. Control Panel'!E33 -> 907200
E28: Other US non-doctoral instutiton | F28: ='2. Control Panel'!E24*'2. Control Panel'!E29*'2. Control Panel'!E34 -> 555000
E29: Other global university | F29: ='2. Control Panel'!E25*'2. Control Panel'!E30*'2. Control Panel'!E35 -> 2315589.7
C30: Serviceable Addressable Market (SAM) | D30: Assumes Liberata’s superior academic metrics position it to capture the entire academic metrics segment globally | G30: =G25 -> 12662990
C31: Serviceable Obtainable Market (SOM) | D31: Reflects Liberata’s ability to scale as a platform and maintain that market over time, supported by its patent and sustained competitive advantage | G31: =G30 -> 12662990
C35: 3. AI Licensing
C37: Level | D37: Method Description | E37: Total Figure
C38: Total Addressable Market (TAM) | D38: Based on global market size data from Grandview Research for the AI datasets and licensing market | E38: ='2. Control Panel'!E37 -> 381800000
C39: Serviceable Addressable Market (SAM) | D39: Represents the portion of the market driven by LLM producers purchasing training data, calculated as 32.4% of the total per Grandview Research | E39: ='2. Control Panel'!E37*'2. Control Panel'!E39 -> 123703200
C40: Serviceable Obtainable Market (SOM) | D40: Reflects the share Liberata can realistically capture as its user base and dataset quality grow—driven by improved research data and replication incentives—calculated by applying an assumed market capture rate to the SAM | E40: ='2. Control Panel'!E37*'2. Control Panel'!E39*'2. Control Panel'!E41 -> 12370320

Sheet 4. Financial Projection Summary
D2: Financial Projection Summary
D4: 1. Revenue Projections Breaks down revenue expectations across various users
D5: 2. Cost Projections Breaks down costs across OpEx and CapEx
D6: 3. Profit Projections Summarizes profit expectations based on revenue and costs
D9: Dropdown adjustment
C10: Sensitivity Analysis - Low/Moderate/High revenue projections | D10: Moderate
C13: Revenue Projections
C15: User Types | D15: User | E15: 2026 | F15: 2027 | G15: 2028 | H15: 2029 | I15: 2030 | J15: 2031 | K15: 2032 | L15: 2033 | M15: 2034 | N15: 2035
C16: Institutions | D16: Universities | E16: {=_xlfn.IFS($D$10="Low",'2. Control Panel'!$L$15*'4.1 Revenue & Cost Breakdown'!D57,'4. Financial Projection Summary'!$D$10="Moderate",'2. Control Panel'!$L$16*'4.1 Revenue & Cost Breakdown'!D57,'4. Financial Projection Summary'!$D$10="High",'2. Control Panel'!$L$17*'4.1 Revenue & Cost Breakdown'!D57)} -> 0 | F16: {=_xlfn.IFS($D$10="Low",'2. Control Panel'!$L$15*'4.1 Revenue & Cost Breakdown'!E57,'4. Financial Projection Summary'!$D$10="Moderate",'2. Control Panel'!$L$16*'4.1 Revenue & Cost Breakdown'!E57,'4. Financial Projection Summary'!$D$10="High",'2. Control Panel'!$L$17*'4.1 Revenue & Cost Breakdown'!E57)} -> 3000000 | G16: {=_xlfn.IFS($D$10="Low",'2. Control Panel'!$L$15*'4.1 Revenue & Cost Breakdown'!F57,'4. Financial Projection Summary'!$D$10="Moderate",'2. Control Panel'!$L$16*'4.1 Revenue & Cost Breakdown'!F57,'4. Financial Projection Summary'!$D$10="High",'2. Control Panel'!$L$17*'4.1 Revenue & Cost Breakdown'!F57)} -> 9000000 | H16: {=_xlfn.IFS($D$10="Low",'2. Control Panel'!$L$15*'4.1 Revenue & Cost Breakdown'!G57,'4. Financial Projection Summary'!$D$10="Moderate",'2. Control Panel'!$L$16*'4.1 Revenue & Cost Breakdown'!G57,'4. Financial Projection Summary'!$D$10="High",'2. Control Panel'!$L$17*'4.1 Revenue & Cost Breakdown'!G57)} -> 14175000 | I16: {=_xlfn.IFS($D$10="Low",'2. Control Panel'!$L$15*'4.1 Revenue & Cost Breakdown'!H57,'4. Financial Projection Summary'!$D$10="Moderate",'2. Control Panel'!$L$16*'4.1 Revenue & Cost Breakdown'!H57,'4. Financial Projection Summary'!$D$10="High",'2. Control Panel'!$L$17*'4.1 Revenue & Cost Breakdown'!H57)} -> 22325625 | J16: {=_xlfn.IFS($D$10="Low",'2. Control Panel'!$L$15*'4.1 Revenue & Cost Breakdown'!I57,'4. Financial Projection Summary'!$D$10="Moderate",'2. Control Panel'!$L$16*'4.1 Revenue & Cost Breakdown'!I57,'4. Financial Projection Summary'!$D$10="High",'2. Control Panel'!$L$17*'4.1 Revenue & Cost Breakdown'!I57)} -> 37507050 | K16: {=_xlfn.IFS($D$10="Low",'2. Control Panel'!$L$15*'4.1 Revenue & Cost Breakdown'!J57,'4. Financial Projection Summary'!$D$10="Moderate",'2. Control Panel'!$L$16*'4.1 Revenue & Cost Breakdown'!J57,'4. Financial Projection Summary'!$D$10="High",'2. Control Panel'!$L$17*'4.1 Revenue & Cost Breakdown'!J57)} -> 61256653 | L16: {=_xlfn.IFS($D$10="Low",'2. Control Panel'!$L$15*'4.1 Revenue & Cost Breakdown'!K57,'4. Financial Projection Summary'!$D$10="Moderate",'2. Control Panel'!$L$16*'4.1 Revenue & Cost Breakdown'!K57,'4. Financial Projection Summary'!$D$10="High",'2. Control Panel'!$L$17*'4.1 Revenue & Cost Breakdown'!K57)} -> 97782567 | ... N16: {=_xlfn.IFS($D$10="Low",'2. Control Panel'!$L$15*'4.1 Revenue & Cost Breakdown'!M57,'4. Financial Projection Summary'!$D$10="Moderate",'2. Control Panel'!$L$16*'4.1 Revenue & Cost Breakdown'!M57,'4. Financial Projection Summary'!$D$10="High",'2. Control Panel'!$L$17*'4.1 Revenue & Cost Breakdown'!M57)} -> 2.1274908e+08
D17: Think Tanks/Non-Profits | E17: {=_xlfn.IFS($D$10="Low",'2. Control Panel'!$L$15*'4.1 Revenue & Cost Breakdown'!D67,'4. Financial Projection Summary'!$D$10="Moderate",'2. Control Panel'!$L$16*'4.1 Revenue & Cost Breakdown'!D67,'4. Financial Projection Summary'!$D$10="High",'2. Control Panel'!$L$17*'4.1 Revenue & Cost Breakdown'!D67)} -> 0 | F17: {=_xlfn.IFS($D$10="Low",'2. Control Panel'!$L$15*'4.1 Revenue & Cost Breakdown'!E67,'4. Financial Projection Summary'!$D$10="Moderate",'2. Control Panel'!$L$16*'4.1 Revenue & Cost Breakdown'!E67,'4. Financial Projection Summary'!$D$10="High",'2. Control Panel'!$L$17*'4.1 Revenue & Cost Breakdown'!E67)} -> 0 | G17: {=_xlfn.IFS($D$10="Low",'2. Control Panel'!$L$15*'4.1 Revenue & Cost Breakdown'!F67,'4. Financial Projection Summary'!$D$10="Moderate",'2. Control Panel'!$L$16*'4.1 Revenue & Cost Breakdown'!F67,'4. Financial Projection Summary'!$D$10="High",'2. Control Panel'!$L$17*'4.1 Revenue & Cost Breakdown'!F67)} -> 0 | H17: {=_xlfn.IFS($D$10="Low",'2. Control Panel'!$L$15*'4.1 Revenue & Cost Breakdown'!G67,'4. Financial Projection Summary'!$D$10="Moderate",'2. Control Panel'!$L$16*'4.1 Revenue & Cost Breakdown'!G67,'4. Financial Projection Summary'!$D$10="High",'2. Control Panel'!$L$17*'4.1 Revenue & Cost Breakdown'!G67)} -> 0 | I17: {=_xlfn.IFS($D$10="Low",'2. Control Panel'!$L$15*'4.1 Revenue & Cost Breakdown'!H67,'4. Financial Projection Summary'!$D$10="Moderate",'2. Control Panel'!$L$16*'4.1 Revenue & Cost Breakdown'!H67,'4. Financial Projection Summary'!$D$10="High",'2. Control Panel'!$L$17*'4.1 Revenue & Cost Breakdown'!H67)} -> 0 | J17: {=_xlfn.IFS($D$10="Low",'2. Control Panel'!$L$15*'4.1 Revenue & Cost Breakdown'!I67,'4. Financial Projection Summary'!$D$10="Moderate",'2. Control Panel'!$L$16*'4.1 Revenue & Cost Breakdown'!I67,'4. Financial Projection Summary'!$D$10="High",'2. Control Panel'!$L$17*'4.1 Revenue & Cost Breakdown'!I67)} -> 173643750 | K17: {=_xlfn.IFS($D$10="Low",'2. Control Panel'!$L$15*'4.1 Revenue & Cost Breakdown'!J67,'4. Financial Projection Summary'!$D$10="Moderate",'2. Control Panel'!$L$16*'4.1 Revenue & Cost Breakdown'!J67,'4. Financial Projection Summary'!$D$10="High",'2. Control Panel'!$L$17*'4.1 Revenue & Cost Breakdown'!J67)} -> 2.0055853e+08 | L17: {=_xlfn.IFS($D$10="Low",'2. Control Panel'!$L$15*'4.1 Revenue & Cost Breakdown'!K67,'4. Financial Projection Summary'!$D$10="Moderate",'2. Control Panel'!$L$16*'4.1 Revenue & Cost Breakdown'!K67,'4. Financial Projection Summary'!$D$10="High",'2. Control Panel'!$L$17*'4.1 Revenue & Cost Breakdown'!K67)} -> 2.316451e+08 | ... N17: {=_xlfn.IFS($D$10="Low",'2. Control Panel'!$L$15*'4.1 Revenue & Cost Breakdown'!M67,'4. Financial Projection Summary'!$D$10="Moderate",'2. Control Panel'!$L$16*'4.1 Revenue & Cost Breakdown'!M67,'4. Financial Projection Summary'!$D$10="High",'2. Control Panel'!$L$17*'4.1 Revenue & Cost Breakdown'!M67)} -> 3.0902036e+08
D18: Government | E18: {=_xlfn.IFS($D$10="Low",'2. Control Panel'!$L$15*'4.1 Revenue & Cost Breakdown'!D77,'4. Financial Projection Summary'!$D$10="Moderate",'2. Control Panel'!$L$16*'4.1 Revenue & Cost Breakdown'!D77,'4. Financial Projection Summary'!$D$10="High",'2. Control Panel'!$L$17*'4.1 Revenue & Cost Breakdown'!D77)} -> 0 | F18: {=_xlfn.IFS($D$10="Low",'2. Control Panel'!$L$15*'4.1 Revenue & Cost Breakdown'!E77,'4. Financial Projection Summary'!$D$10="Moderate",'2. Control Panel'!$L$16*'4.1 Revenue & Cost Breakdown'!E77,'4. Financial Projection Summary'!$D$10="High",'2. Control Panel'!$L$17*'4.1 Revenue & Cost Breakdown'!E77)} -> 0 | G18: {=_xlfn.IFS($D$10="Low",'2. Control Panel'!$L$15*'4.1 Revenue & Cost Breakdown'!F77,'4. Financial Projection Summary'!$D$10="Moderate",'2. Control Panel'!$L$16*'4.1 Revenue & Cost Breakdown'!F77,'4. Financial Projection Summary'!$D$10="High",'2. Control Panel'!$L$17*'4.1 Revenue & Cost Breakdown'!F77)} -> 0 | H18: {=_xlfn.IFS($D$10="Low",'2. Control Panel'!$L$15*'4.1 Revenue & Cost Breakdown'!G77,'4. Financial Projection Summary'!$D$10="Moderate",'2. Control Panel'!$L$16*'4.1 Revenue & Cost Breakdown'!G77,'4. Financial Projection Summary'!$D$10="High",'2. Control Panel'!$L$17*'4.1 Revenue & Cost Breakdown'!G77)} -> 0 | I18: {=_xlfn.IFS($D$10="Low",'2. Control Panel'!$L$15*'4.1 Revenue & Cost Breakdown'!H77,'4. Financial Projection Summary'!$D$10="Moderate",'2. Control Panel'!$L$16*'4.1 Revenue & Cost Breakdown'!H77,'4. Financial Projection Summary'!$D$10="High",'2. Control Panel'!$L$17*'4.1 Revenue & Cost Breakdown'!H77)} -> 0 | J18: {=_xlfn.IFS($D$10="Low",'2. Control Panel'!$L$15*'4.1 Revenue & Cost Breakdown'!I77,'4. Financial Projection Summary'!$D$10="Moderate",'2. Control Panel'!$L$16*'4.1 Revenue & Cost Breakdown'!I77,'4. Financial Projection Summary'!$D$10="High",'2. Control Panel'!$L$17*'4.1 Revenue & Cost Breakdown'!I77)} -> 28940625 | K18: {=_xlfn.IFS($D$10="Low",'2. Control Panel'!$L$15*'4.1 Revenue & Cost Breakdown'!J77,'4. Financial Projection Summary'!$D$10="Moderate",'2. Control Panel'!$L$16*'4.1 Revenue & Cost Breakdown'!J77,'4. Financial Projection Summary'!$D$10="High",'2. Control Panel'!$L$17*'4.1 Revenue & Cost Breakdown'!J77)} -> 33426422 | L18: {=_xlfn.IFS($D$10="Low",'2. Control Panel'!$L$15*'4.1 Revenue & Cost Breakdown'!K77,'4. Financial Projection Summary'!$D$10="Moderate",'2. Control Panel'!$L$16*'4.1 Revenue & Cost Breakdown'!K77,'4. Financial Projection Summary'!$D$10="High",'2. Control Panel'!$L$17*'4.1 Revenue & Cost Breakdown'!K77)} -> 38607517 | ... N18: {=_xlfn.IFS($D$10="Low",'2. Control Panel'!$L$15*'4.1 Revenue & Cost Breakdown'!M77,'4. Financial Projection Summary'!$D$10="Moderate",'2. Control Panel'!$L$16*'4.1 Revenue & Cost Breakdown'!M77,'4. Financial Projection Summary'!$D$10="High",'2. Control Panel'!$L$17*'4.1 Revenue & Cost Breakdown'!M77)} -> 51503393
D19: Instutions - Totals | E19: =SUM(E16:E18) -> 0 | F19: =SUM(F16:F18) -> 3000000 | G19: =SUM(G16:G18) -> 9000000 | H19: =SUM(H16:H18) -> 14175000 | I19: =SUM(I16:I18) -> 22325625 | J19: =SUM(J16:J18) -> 240091425 | K19: =SUM(K16:K18) -> 2.9524161e+08 | L19: =SUM(L16:L18) -> 3.6803519e+08 | ... N19: =SUM(N16:N18) -> 5.7327283e+08
C20: Private Industry | D20: Corporations | E20: {=_xlfn.IFS($D$10="Low",'2. Control Panel'!$L$15*'4.1 Revenue & Cost Breakdown'!D87,'4. Financial Projection Summary'!$D$10="Moderate",'2. Control Panel'!$L$16*'4.1 Revenue & Cost Breakdown'!D87,'4. Financial Projection Summary'!$D$10="High",'2. Control Panel'!$L$17*'4.1 Revenue & Cost Breakdown'!D87)} -> 0 | F20: {=_xlfn.IFS($D$10="Low",'2. Control Panel'!$L$15*'4.1 Revenue & Cost Breakdown'!E87,'4. Financial Projection Summary'!$D$10="Moderate",'2. Control Panel'!$L$16*'4.1 Revenue & Cost Breakdown'!E87,'4. Financial Projection Summary'!$D$10="High",'2. Control Panel'!$L$17*'4.1 Revenue & Cost Breakdown'!E87)} -> 0 | G20: {=_xlfn.IFS($D$10="Low",'2. Control Panel'!$L$15*'4.1 Revenue & Cost Breakdown'!F87,'4. Financial Projection Summary'!$D$10="Moderate",'2. Control Panel'!$L$16*'4.1 Revenue & Cost Breakdown'!F87,'4. Financial Projection Summary'!$D$10="High",'2. Control Panel'!$L$17*'4.1 Revenue & Cost Breakdown'!F87)} -> 0 | H20: {=_xlfn.IFS($D$10="Low",'2. Control Panel'!$L$15*'4.1 Revenue & Cost Breakdown'!G87,'4. Financial Projection Summary'!$D$10="Moderate",'2. Control Panel'!$L$16*'4.1 Revenue & Cost Breakdown'!G87,'4. Financial Projection Summary'!$D$10="High",'2. Control Panel'!$L$17*'4.1 Revenue & Cost Breakdown'!G87)} -> 0 | I20: {=_xlfn.IFS($D$10="Low",'2. Control Panel'!$L$15*'4.1 Revenue & Cost Breakdown'!H87,'4. Financial Projection Summary'!$D$10="Moderate",'2. Control Panel'!$L$16*'4.1 Revenue & Cost Breakdown'!H87,'4. Financial Projection Summary'!$D$10="High",'2. Control Panel'!$L$17*'4.1 Revenue & Cost Breakdown'!H87)} -> 0 | J20: {=_xlfn.IFS($D$10="Low",'2. Control Panel'!$L$15*'4.1 Revenue & Cost Breakdown'!I87,'4. Financial Projection Summary'!$D$10="Moderate",'2. Control Panel'!$L$16*'4.1 Revenue & Cost Breakdown'!I87,'4. Financial Projection Summary'!$D$10="High",'2. Control Panel'!$L$17*'4.1 Revenue & Cost Breakdown'!I87)} -> 57881250 | K20: {=_xlfn.IFS($D$10="Low",'2. Control Panel'!$L$15*'4.1 Revenue & Cost Breakdown'!J87,'4. Financial Projection Summary'!$D$10="Moderate",'2. Control Panel'!$L$16*'4.1 Revenue & Cost Breakdown'!J87,'4. Financial Projection Summary'!$D$10="High",'2. Control Panel'!$L$17*'4.1 Revenue & Cost Breakdown'!J87)} -> 66852844 | L20: {=_xlfn.IFS($D$10="Low",'2. Control Panel'!$L$15*'4.1 Revenue & Cost Breakdown'!K87,'4. Financial Projection Summary'!$D$10="Moderate",'2. Control Panel'!$L$16*'4.1 Revenue & Cost Breakdown'!K87,'4. Financial Projection Summary'!$D$10="High",'2. Control Panel'!$L$17*'4.1 Revenue & Cost Breakdown'!K87)} -> 77215035 | ... N20: {=_xlfn.IFS($D$10="Low",'2. Control Panel'!$L$15*'4.1 Revenue & Cost Breakdown'!M87,'4. Financial Projection Summary'!$D$10="Moderate",'2. Control Panel'!$L$16*'4.1 Revenue & Cost Breakdown'!M87,'4. Financial Projection Summary'!$D$10="High",'2. Control Panel'!$L$17*'4.1 Revenue & Cost Breakdown'!M87)} -> 1.0300679e+08
D21: Publishing Organizations | E21: {=_xlfn.IFS($D$10="Low",'2. Control Panel'!$L$15*'4.1 Revenue & Cost Breakdown'!D97,'4. Financial Projection Summary'!$D$10="Moderate",'2. Control Panel'!$L$16*'4.1 Revenue & Cost Breakdown'!D97,'4. Financial Projection Summary'!$D$10="High",'2. Control Panel'!$L$17*'4.1 Revenue & Cost Breakdown'!D97)} -> 0 | F21: {=_xlfn.IFS($D$10="Low",'2. Control Panel'!$L$15*'4.1 Revenue & Cost Breakdown'!E97,'4. Financial Projection Summary'!$D$10="Moderate",'2. Control Panel'!$L$16*'4.1 Revenue & Cost Breakdown'!E97,'4. Financial Projection Summary'!$D$10="High",'2. Control Panel'!$L$17*'4.1 Revenue & Cost Breakdown'!E97)} -> 0 | G21: {=_xlfn.IFS($D$10="Low",'2. Control Panel'!$L$15*'4.1 Revenue & Cost Breakdown'!F97,'4. Financial Projection Summary'!$D$10="Moderate",'2. Control Panel'!$L$16*'4.1 Revenue & Cost Breakdown'!F97,'4. Financial Projection Summary'!$D$10="High",'2. Control Panel'!$L$17*'4.1 Revenue & Cost Breakdown'!F97)} -> 0 | H21: {=_xlfn.IFS($D$10="Low",'2. Control Panel'!$L$15*'4.1 Revenue & Cost Breakdown'!G97,'4. Financial Projection Summary'!$D$10="Moderate",'2. Control Panel'!$L$16*'4.1 Revenue & Cost Breakdown'!G97,'4. Financial Projection Summary'!$D$10="High",'2. Control Panel'!$L$17*'4.1 Revenue & Cost Breakdown'!G97)} -> 0 | I21: {=_xlfn.IFS($D$10="Low",'2. Control Panel'!$L$15*'4.1 Revenue & Cost Breakdown'!H97,'4. Financial Projection Summary'!$D$10="Moderate",'2. Control Panel'!$L$16*'4.1 Revenue & Cost Breakdown'!H97,'4. Financial Projection Summary'!$D$10="High",'2. Control Panel'!$L$17*'4.1 Revenue & Cost Breakdown'!H97)} -> 0 | J21: {=_xlfn.IFS($D$10="Low",'2. Control Panel'!$L$15*'4.1 Revenue & Cost Breakdown'!I97,'4. Financial Projection Summary'!$D$10="Moderate",'2. Control Panel'!$L$16*'4.1 Revenue & Cost Breakdown'!I97,'4. Financial Projection Summary'!$D$10="High",'2. Control Panel'!$L$17*'4.1 Revenue & Cost Breakdown'!I97)} -> 578812.5 | K21: {=_xlfn.IFS($D$10="Low",'2. Control Panel'!$L$15*'4.1 Revenue & Cost Breakdown'!J97,'4. Financial Projection Summary'!$D$10="Moderate",'2. Control Panel'!$L$16*'4.1 Revenue & Cost Breakdown'!J97,'4. Financial Projection Summary'!$D$10="High",'2. Control Panel'!$L$17*'4.1 Revenue & Cost Breakdown'!J97)} -> 668528.44 | L21: {=_xlfn.IFS($D$10="Low",'2. Control Panel'!$L$15*'4.1 Revenue & Cost Breakdown'!K97,'4. Financial Projection Summary'!$D$10="Moderate",'2. Control Panel'!$L$16*'4.1 Revenue & Cost Breakdown'!K97,'4. Financial Projection Summary'!$D$10="High",'2. Control Panel'!$L$17*'4.1 Revenue & Cost Breakdown'!K97)} -> 772150.35 | ... N21: {=_xlfn.IFS($D$10="Low",'2. Control Panel'!$L$15*'4.1 Revenue & Cost Breakdown'!M97,'4. Financial Projection Summary'!$D$10="Moderate",'2. Control Panel'!$L$16*'4.1 Revenue & Cost Breakdown'!M97,'4. Financial Projection Summary'!$D$10="High",'2. Control Panel'!$L$17*'4.1 Revenue & Cost Breakdown'!M97)} -> 1030067.9
D22: Rankings Organizations | E22: {=_xlfn.IFS($D$10="Low",'2. Control Panel'!$L$15*'4.1 Revenue & Cost Breakdown'!D107,'4. Financial Projection Summary'!$D$10="Moderate",'2. Control Panel'!$L$16*'4.1 Revenue & Cost Breakdown'!D107,'4. Financial Projection Summary'!$D$10="High",'2. Control Panel'!$L$17*'4.1 Revenue & Cost Breakdown'!D107)} -> 0 | F22: {=_xlfn.IFS($D$10="Low",'2. Control Panel'!$L$15*'4.1 Revenue & Cost Breakdown'!E107,'4. Financial Projection Summary'!$D$10="Moderate",'2. Control Panel'!$L$16*'4.1 Revenue & Cost Breakdown'!E107,'4. Financial Projection Summary'!$D$10="High",'2. Control Panel'!$L$17*'4.1 Revenue & Cost Breakdown'!E107)} -> 0 | G22: {=_xlfn.IFS($D$10="Low",'2. Control Panel'!$L$15*'4.1 Revenue & Cost Breakdown'!F107,'4. Financial Projection Summary'!$D$10="Moderate",'2. Control Panel'!$L$16*'4.1 Revenue & Cost Breakdown'!F107,'4. Financial Projection Summary'!$D$10="High",'2. Control Panel'!$L$17*'4.1 Revenue & Cost Breakdown'!F107)} -> 0 | H22: {=_xlfn.IFS($D$10="Low",'2. Control Panel'!$L$15*'4.1 Revenue & Cost Breakdown'!G107,'4. Financial Projection Summary'!$D$10="Moderate",'2. Control Panel'!$L$16*'4.1 Revenue & Cost Breakdown'!G107,'4. Financial Projection Summary'!$D$10="High",'2. Control Panel'!$L$17*'4.1 Revenue & Cost Breakdown'!G107)} -> 0 | I22: {=_xlfn.IFS($D$10="Low",'2. Control Panel'!$L$15*'4.1 Revenue & Cost Breakdown'!H107,'4. Financial Projection Summary'!$D$10="Moderate",'2. Control Panel'!$L$16*'4.1 Revenue & Cost Breakdown'!H107,'4. Financial Projection Summary'!$D$10="High",'2. Control Panel'!$L$17*'4.1 Revenue & Cost Breakdown'!H107)} -> 0 | J22: {=_xlfn.IFS($D$10="Low",'2. Control Panel'!$L$15*'4.1 Revenue & Cost Breakdown'!I107,'4. Financial Projection Summary'!$D$10="Moderate",'2. Control Panel'!$L$16*'4.1 Revenue & Cost Breakdown'!I107,'4. Financial Projection Summary'!$D$10="High",'2. Control Panel'!$L$17*'4.1 Revenue & Cost Breakdown'!I107)} -> 347287.5 | K22: {=_xlfn.IFS($D$10="Low",'2. Control Panel'!$L$15*'4.1 Revenue & Cost Breakdown'!J107,'4. Financial Projection Summary'!$D$10="Moderate",'2. Control Panel'!$L$16*'4.1 Revenue & Cost Breakdown'!J107,'4. Financial Projection Summary'!$D$10="High",'2. Control Panel'!$L$17*'4.1 Revenue & Cost Breakdown'!J107)} -> 401117.06 | L22: {=_xlfn.IFS($D$10="Low",'2. Control Panel'!$L$15*'4.1 Revenue & Cost Breakdown'!K107,'4. Financial Projection Summary'!$D$10="Moderate",'2. Control Panel'!$L$16*'4.1 Revenue & Cost Breakdown'!K107,'4. Financial Projection Summary'!$D$10="High",'2. Control Panel'!$L$17*'4.1 Revenue & Cost Breakdown'!K107)} -> 463290.21 | ... N22: {=_xlfn.IFS($D$10="Low",'2. Control Panel'!$L$15*'4.1 Revenue & Cost Breakdown'!M107,'4. Financial Projection Summary'!$D$10="Moderate",'2. Control Panel'!$L$16*'4.1 Revenue & Cost Breakdown'!M107,'4. Financial Projection Summary'!$D$10="High",'2. Control Panel'!$L$17*'4.1 Revenue & Cost Breakdown'!M107)} -> 618040.72
D23: Private Industry - Totals | E23: =SUM(E20:E22) -> 0 | F23: =SUM(F20:F22) -> 0 | G23: =SUM(G20:G22) -> 0 | H23: =SUM(H20:H22) -> 0 | I23: =SUM(I20:I22) -> 0 | J23: =SUM(J20:J22) -> 58807350 | K23: =SUM(K20:K22) -> 67922489 | L23: =SUM(L20:L22) -> 78450475 | ... N23: =SUM(N20:N22) -> 1.046549e+08
D24: TOTAL | E24: =SUM(E19,E23) -> 0 | F24: =SUM(F19,F23) -> 3000000 | G24: =SUM(G19,G23) -> 9000000 | H24: =SUM(H19,H23) -> 14175000 | I24: =SUM(I19,I23) -> 22325625 | J24: =SUM(J19,J23) -> 298898775 | K24: =SUM(K19,K23) -> 3.631641e+08 | L24: =SUM(L19,L23) -> 4.4648566e+08 | ... N24: =SUM(N19,N23) -> 6.7792773e+08
D28: Dropdown adjustment
C29: Sensitivity Analysis - Low/Moderate/High cost projections | D29: Moderate
C31: Cost Projections
C33: User Types | E33: 2026 | F33: 2027 | G33: 2028 | H33: 2029 | I33: 2030 | J33: 2031 | K33: 2032 | L33: 2033 | M33: 2034 | N33: 2035
C34: Operating Expenses (OpEx) | D34: Salary & Wages | E34: {=_xlfn.IFS($D$29="Low",'2. Control Panel'!$L$15*SUM('4.1 Revenue & Cost Breakdown'!D120,'4.1 Revenue & Cost Breakdown'!D122,'4.1 Revenue & Cost Breakdown'!D124,'4.1 Revenue & Cost Breakdown'!D126),'4. Financial Projection Summary'!$D$29="Moderate",'2. Control Panel'!$L$16*SUM('4.1 Revenue & Cost Breakdown'!D120,'4.1 Revenue & Cost Breakdown'!D122,'4.1 Revenue & Cost Breakdown'!D124,'4.1 Revenue & Cost Breakdown'!D126),'4. Financial Projection Summary'!$D$29="High",'2. Control Panel'!$L$17*SUM('4.1 Revenue & Cost Breakdown'!D120,'4.1 Revenue & Cost Breakdown'!D122,'4.1 Revenue & Cost Breakdown'!D124,'4.1 Revenue & Cost Breakdown'!D126))} -> 2480000 | F34: {=_xlfn.IFS($D$29="Low",'2. Control Panel'!$L$15*SUM('4.1 Revenue & Cost Breakdown'!E120,'4.1 Revenue & Cost Breakdown'!E122,'4.1 Revenue & Cost Breakdown'!E124,'4.1 Revenue & Cost Breakdown'!E126),'4. Financial Projection Summary'!$D$29="Moderate",'2. Control Panel'!$L$16*SUM('4.1 Revenue & Cost Breakdown'!E120,'4.1 Revenue & Cost Breakdown'!E122,'4.1 Revenue & Cost Breakdown'!E124,'4.1 Revenue & Cost Breakdown'!E126),'4. Financial Projection Summary'!$D$29="High",'2. Control Panel'!$L$17*SUM('4.1 Revenue & Cost Breakdown'!E120,'4.1 Revenue & Cost Breakdown'!E122,'4.1 Revenue & Cost Breakdown'!E124,'4.1 Revenue & Cost Breakdown'!E126))} -> 2613000 | G34: {=_xlfn.IFS($D$29="Low",'2. Control Panel'!$L$15*SUM('4.1 Revenue & Cost Breakdown'!F120,'4.1 Revenue & Cost Breakdown'!F122,'4.1 Revenue & Cost Breakdown'!F124,'4.1 Revenue & Cost Breakdown'!F126),'4. Financial Projection Summary'!$D$29="Moderate",'2. Control Panel'!$L$16*SUM('4.1 Revenue & Cost Breakdown'!F120,'4.1 Revenue & Cost Breakdown'!F122,'4.1 Revenue & Cost Breakdown'!F124,'4.1 Revenue & Cost Breakdown'!F126),'4. Financial Projection Summary'!$D$29="High",'2. Control Panel'!$L$17*SUM('4.1 Revenue & Cost Breakdown'!F120,'4.1 Revenue & Cost Breakdown'!F122,'4.1 Revenue & Cost Breakdown'!F124,'4.1 Revenue & Cost Breakdown'!F126))} -> 3904800 | H34: {=_xlfn.IFS($D$29="Low",'2. Control Panel'!$L$15*SUM('4.1 Revenue & Cost Breakdown'!G120,'4.1 Revenue & Cost Breakdown'!G122,'4.1 Revenue & Cost Breakdown'!G124,'4.1 Revenue & Cost Breakdown'!G126),'4. Financial Projection Summary'!$D$29="Moderate",'2. Control Panel'!$L$16*SUM('4.1 Revenue & Cost Breakdown'!G120,'4.1 Revenue & Cost Breakdown'!G122,'4.1 Revenue & Cost Breakdown'!G124,'4.1 Revenue & Cost Breakdown'!G126),'4. Financial Projection Summary'!$D$29="High",'2. Control Panel'!$L$17*SUM('4.1 Revenue & Cost Breakdown'!G120,'4.1 Revenue & Cost Breakdown'!G122,'4.1 Revenue & Cost Breakdown'!G124,'4.1 Revenue & Cost Breakdown'!G126))} -> 4168530 | I34: {=_xlfn.IFS($D$29="Low",'2. Control Panel'!$L$15*SUM('4.1 Revenue & Cost Breakdown'!H120,'4.1 Revenue & Cost Breakdown'!H122,'4.1 Revenue & Cost Breakdown'!H124,'4.1 Revenue & Cost Breakdown'!H126),'4. Financial Projection Summary'!$D$29="Moderate",'2. Control Panel'!$L$16*SUM('4.1 Revenue & Cost Breakdown'!H120,'4.1 Revenue & Cost Breakdown'!H122,'4.1 Revenue & Cost Breakdown'!H124,'4.1 Revenue & Cost Breakdown'!H126),'4. Financial Projection Summary'!$D$29="High",'2. Control Panel'!$L$17*SUM('4.1 Revenue & Cost Breakdown'!H120,'4.1 Revenue & Cost Breakdown'!H122,'4.1 Revenue & Cost Breakdown'!H124,'4.1 Revenue & Cost Breakdown'!H126))} -> 6349896 | J34: {=_xlfn.IFS($D$29="Low",'2. Control Panel'!$L$15*SUM('4.1 Revenue & Cost Breakdown'!I120,'4.1 Revenue & Cost Breakdown'!I122,'4.1 Revenue & Cost Breakdown'!I124,'4.1 Revenue & Cost Breakdown'!I126),'4. Financial Projection Summary'!$D$29="Moderate",'2. Control Panel'!$L$16*SUM('4.1 Revenue & Cost Breakdown'!I120,'4.1 Revenue & Cost Breakdown'!I122,'4.1 Revenue & Cost Breakdown'!I124,'4.1 Revenue & Cost Breakdown'!I126),'4. Financial Projection Summary'!$D$29="High",'2. Control Panel'!$L$17*SUM('4.1 Revenue & Cost Breakdown'!I120,'4.1 Revenue & Cost Breakdown'!I122,'4.1 Revenue & Cost Breakdown'!I124,'4.1 Revenue & Cost Breakdown'!I126))} -> 6749321.9 | K34: {=_xlfn.IFS($D$29="Low",'2. Control Panel'!$L$15*SUM('4.1 Revenue & Cost Breakdown'!J120,'4.1 Revenue & Cost Breakdown'!J122,'4.1 Revenue & Cost Breakdown'!J124,'4.1 Revenue & Cost Breakdown'!J126),'4. Financial Projection Summary'!$D$29="Moderate",'2. Control Panel'!$L$16*SUM('4.1 Revenue & Cost Breakdown'!J120,'4.1 Revenue & Cost Breakdown'!J122,'4.1 Revenue & Cost Breakdown'!J124,'4.1 Revenue & Cost Breakdown'!J126),'4. Financial Projection Summary'!$D$29="High",'2. Control Panel'!$L$17*SUM('4.1 Revenue & Cost Breakdown'!J120,'4.1 Revenue & Cost Breakdown'!J122,'4.1 Revenue & Cost Breakdown'!J124,'4.1 Revenue & Cost Breakdown'!J126))} -> 7176408.4 | L34: {=_xlfn.IFS($D$29="Low",'2. Control Panel'!$L$15*SUM('4.1 Revenue & Cost Breakdown'!K120,'4.1 Revenue & Cost Breakdown'!K122,'4.1 Revenue & Cost Breakdown'!K124,'4.1 Revenue & Cost Breakdown'!K126),'4. Financial Projection Summary'!$D$29="Moderate",'2. Control Panel'!$L$16*SUM('4.1 Revenue & Cost Breakdown'!K120,'4.1 Revenue & Cost Breakdown'!K122,'4.1 Revenue & Cost Breakdown'!K124,'4.1 Revenue & Cost Breakdown'!K126),'4. Financial Projection Summary'!$D$29="High",'2. Control Panel'!$L$17*SUM('4.1 Revenue & Cost Breakdown'!K120,'4.1 Revenue & Cost Breakdown'!K122,'4.1 Revenue & Cost Breakdown'!K124,'4.1 Revenue & Cost Breakdown'!K126))} -> 7633267 | ... N34: {=_xlfn.IFS($D$29="Low",'2. Control Panel'!$L$15*SUM('4.1 Revenue & Cost Breakdown'!M120,'4.1 Revenue & Cost Breakdown'!M122,'4.1 Revenue & Cost Breakdown'!M124,'4.1 Revenue & Cost Breakdown'!M126),'4. Financial Projection Summary'!$D$29="Moderate",'2. Control Panel'!$L$16*SUM('4.1 Revenue & Cost Breakdown'!M120,'4.1 Revenue & Cost Breakdown'!M122,'4.1 Revenue & Cost Breakdown'!M124,'4.1 Revenue & Cost Breakdown'!M126),'4. Financial Projection Summary'!$D$29="High",'2. Control Panel'!$L$17*SUM('4.1 Revenue & Cost Breakdown'!M120,'4.1 Revenue & Cost Breakdown'!M122,'4.1 Revenue & Cost Breakdown'!M124,'4.1 Revenue & Cost Breakdown'!M126))} -> 8645638.9
D35: Cloud & Compute + AI Training | E35: {=_xlfn.IFS($D$29="Low",'2. Control Panel'!$L$15*SUM('4.1 Revenue & Cost Breakdown'!D128,'4.1 Revenue & Cost Breakdown'!D134),'4. Financial Projection Summary'!$D$29="Moderate",'2. Control Panel'!$L$16*SUM('4.1 Revenue & Cost Breakdown'!D128,'4.1 Revenue & Cost Breakdown'!D134),'4. Financial Projection Summary'!$D$29="High",'2. Control Panel'!$L$17*SUM('4.1 Revenue & Cost Breakdown'!D128,'4.1 Revenue & Cost Breakdown'!D134))} -> 25000 | F35: {=_xlfn.IFS($D$29="Low",'2. Control Panel'!$L$15*SUM('4.1 Revenue & Cost Breakdown'!E128,'4.1 Revenue & Cost Breakdown'!E134),'4. Financial Projection Summary'!$D$29="Moderate",'2. Control Panel'!$L$16*SUM('4.1 Revenue & Cost Breakdown'!E128,'4.1 Revenue & Cost Breakdown'!E134),'4. Financial Projection Summary'!$D$29="High",'2. Control Panel'!$L$17*SUM('4.1 Revenue & Cost Breakdown'!E128,'4.1 Revenue & Cost Breakdown'!E134))} -> 27500 | G35: {=_xlfn.IFS($D$29="Low",'2. Control Panel'!$L$15*SUM('4.1 Revenue & Cost Breakdown'!F128,'4.1 Revenue & Cost Breakdown'!F134),'4. Financial Projection Summary'!$D$29="Moderate",'2. Control Panel'!$L$16*SUM('4.1 Revenue & Cost Breakdown'!F128,'4.1 Revenue & Cost Breakdown'!F134),'4. Financial Projection Summary'!$D$29="High",'2. Control Panel'!$L$17*SUM('4.1 Revenue & Cost Breakdown'!F128,'4.1 Revenue & Cost Breakdown'!F134))} -> 55250 | H35: {=_xlfn.IFS($D$29="Low",'2. Control Panel'!$L$15*SUM('4.1 Revenue & Cost Breakdown'!G128,'4.1 Revenue & Cost Breakdown'!G134),'4. Financial Projection Summary'!$D$29="Moderate",'2. Control Panel'!$L$16*SUM('4.1 Revenue & Cost Breakdown'!G128,'4.1 Revenue & Cost Breakdown'!G134),'4. Financial Projection Summary'!$D$29="High",'2. Control Panel'!$L$17*SUM('4.1 Revenue & Cost Breakdown'!G128,'4.1 Revenue & Cost Breakdown'!G134))} -> 62025 | I35: {=_xlfn.IFS($D$29="Low",'2. Control Panel'!$L$15*SUM('4.1 Revenue & Cost Breakdown'!H128,'4.1 Revenue & Cost Breakdown'!H134),'4. Financial Projection Summary'!$D$29="Moderate",'2. Control Panel'!$L$16*SUM('4.1 Revenue & Cost Breakdown'!H128,'4.1 Revenue & Cost Breakdown'!H134),'4. Financial Projection Summary'!$D$29="High",'2. Control Panel'!$L$17*SUM('4.1 Revenue & Cost Breakdown'!H128,'4.1 Revenue & Cost Breakdown'!H134))} -> 69665 | J35: {=_xlfn.IFS($D$29="Low",'2. Control Panel'!$L$15*SUM('4.1 Revenue & Cost Breakdown'!I128,'4.1 Revenue & Cost Breakdown'!I134),'4. Financial Projection Summary'!$D$29="Moderate",'2. Control Panel'!$L$16*SUM('4.1 Revenue & Cost Breakdown'!I128,'4.1 Revenue & Cost Breakdown'!I134),'4. Financial Projection Summary'!$D$29="High",'2. Control Panel'!$L$17*SUM('4.1 Revenue & Cost Breakdown'!I128,'4.1 Revenue & Cost Breakdown'!I134))} -> 78284.625 | K35: {=_xlfn.IFS($D$29="Low",'2. Control Panel'!$L$15*SUM('4.1 Revenue & Cost Breakdown'!J128,'4.1 Revenue & Cost Breakdown'!J134),'4. Financial Projection Summary'!$D$29="Moderate",'2. Control Panel'!$L$16*SUM('4.1 Revenue & Cost Breakdown'!J128,'4.1 Revenue & Cost Breakdown'!J134),'4. Financial Projection Summary'!$D$29="High",'2. Control Panel'!$L$17*SUM('4.1 Revenue & Cost Breakdown'!J128,'4.1 Revenue & Cost Breakdown'!J134))} -> 88014.181 | L35: {=_xlfn.IFS($D$29="Low",'2. Control Panel'!$L$15*SUM('4.1 Revenue & Cost Breakdown'!K128,'4.1 Revenue & Cost Breakdown'!K134),'4. Financial Projection Summary'!$D$29="Moderate",'2. Control Panel'!$L$16*SUM('4.1 Revenue & Cost Breakdown'!K128,'4.1 Revenue & Cost Breakdown'!K134),'4. Financial Projection Summary'!$D$29="High",'2. Control Panel'!$L$17*SUM('4.1 Revenue & Cost Breakdown'!K128,'4.1 Revenue & Cost Breakdown'!K134))} -> 99001.857 | ... N35: {=_xlfn.IFS($D$29="Low",'2. Control Panel'!$L$15*SUM('4.1 Revenue & Cost Breakdown'!M128,'4.1 Revenue & Cost Breakdown'!M134),'4. Financial Projection Summary'!$D$29="Moderate",'2. Control Panel'!$L$16*SUM('4.1 Revenue & Cost Breakdown'!M128,'4.1 Revenue & Cost Breakdown'!M134),'4. Financial Projection Summary'!$D$29="High",'2. Control Panel'!$L$17*SUM('4.1 Revenue & Cost Breakdown'!M128,'4.1 Revenue & Cost Breakdown'!M134))} -> 125449.19
D36: Marketing & Outreach | E36: {=_xlfn.IFS($D$29="Low",'2. Control Panel'!$L$15*'4.1 Revenue & Cost Breakdown'!D130,'4. Financial Projection Summary'!$D$29="Moderate",'2. Control Panel'!$L$16*'4.1 Revenue & Cost Breakdown'!D130,'4. Financial Projection Summary'!$D$29="High",'2. Control Panel'!$L$17*'4.1 Revenue & Cost Breakdown'!D130)} -> 100000 | F36: {=_xlfn.IFS($D$29="Low",'2. Control Panel'!$L$15*'4.1 Revenue & Cost Breakdown'!E130,'4. Financial Projection Summary'!$D$29="Moderate",'2. Control Panel'!$L$16*'4.1 Revenue & Cost Breakdown'!E130,'4. Financial Projection Summary'!$D$29="High",'2. Control Panel'!$L$17*'4.1 Revenue & Cost Breakdown'!E130)} -> 110000 | G36: {=_xlfn.IFS($D$29="Low",'2. Control Panel'!$L$15*'4.1 Revenue & Cost Breakdown'!F130,'4. Financial Projection Summary'!$D$29="Moderate",'2. Control Panel'!$L$16*'4.1 Revenue & Cost Breakdown'!F130,'4. Financial Projection Summary'!$D$29="High",'2. Control Panel'!$L$17*'4.1 Revenue & Cost Breakdown'!F130)} -> 121000 | H36: {=_xlfn.IFS($D$29="Low",'2. Control Panel'!$L$15*'4.1 Revenue & Cost Breakdown'!G130,'4. Financial Projection Summary'!$D$29="Moderate",'2. Control Panel'!$L$16*'4.1 Revenue & Cost Breakdown'!G130,'4. Financial Projection Summary'!$D$29="High",'2. Control Panel'!$L$17*'4.1 Revenue & Cost Breakdown'!G130)} -> 133100 | I36: {=_xlfn.IFS($D$29="Low",'2. Control Panel'!$L$15*'4.1 Revenue & Cost Breakdown'!H130,'4. Financial Projection Summary'!$D$29="Moderate",'2. Control Panel'!$L$16*'4.1 Revenue & Cost Breakdown'!H130,'4. Financial Projection Summary'!$D$29="High",'2. Control Panel'!$L$17*'4.1 Revenue & Cost Breakdown'!H130)} -> 146410 | J36: {=_xlfn.IFS($D$29="Low",'2. Control Panel'!$L$15*'4.1 Revenue & Cost Breakdown'!I130,'4. Financial Projection Summary'!$D$29="Moderate",'2. Control Panel'!$L$16*'4.1 Revenue & Cost Breakdown'!I130,'4. Financial Projection Summary'!$D$29="High",'2. Control Panel'!$L$17*'4.1 Revenue & Cost Breakdown'!I130)} -> 161051 | K36: {=_xlfn.IFS($D$29="Low",'2. Control Panel'!$L$15*'4.1 Revenue & Cost Breakdown'!J130,'4. Financial Projection Summary'!$D$29="Moderate",'2. Control Panel'!$L$16*'4.1 Revenue & Cost Breakdown'!J130,'4. Financial Projection Summary'!$D$29="High",'2. Control Panel'!$L$17*'4.1 Revenue & Cost Breakdown'!J130)} -> 177156.1 | L36: {=_xlfn.IFS($D$29="Low",'2. Control Panel'!$L$15*'4.1 Revenue & Cost Breakdown'!K130,'4. Financial Projection Summary'!$D$29="Moderate",'2. Control Panel'!$L$16*'4.1 Revenue & Cost Breakdown'!K130,'4. Financial Projection Summary'!$D$29="High",'2. Control Panel'!$L$17*'4.1 Revenue & Cost Breakdown'!K130)} -> 194871.71 | ... N36: {=_xlfn.IFS($D$29="Low",'2. Control Panel'!$L$15*'4.1 Revenue & Cost Breakdown'!M130,'4. Financial Projection Summary'!$D$29="Moderate",'2. Control Panel'!$L$16*'4.1 Revenue & Cost Breakdown'!M130,'4. Financial Projection Summary'!$D$29="High",'2. Control Panel'!$L$17*'4.1 Revenue & Cost Breakdown'!M130)} -> 235794.77
D37: SG&A | E37: {=_xlfn.IFS($D$29="Low",'2. Control Panel'!$L$15*'4.1 Revenue & Cost Breakdown'!D132,'4. Financial Projection Summary'!$D$29="Moderate",'2. Control Panel'!$L$16*'4.1 Revenue & Cost Breakdown'!D132,'4. Financial Projection Summary'!$D$29="High",'2. Control Panel'!$L$17*'4.1 Revenue & Cost Breakdown'!D132)} -> 50000 | F37: {=_xlfn.IFS($D$29="Low",'2. Control Panel'!$L$15*'4.1 Revenue & Cost Breakdown'!E132,'4. Financial Projection Summary'!$D$29="Moderate",'2. Control Panel'!$L$16*'4.1 Revenue & Cost Breakdown'!E132,'4. Financial Projection Summary'!$D$29="High",'2. Control Panel'!$L$17*'4.1 Revenue & Cost Breakdown'!E132)} -> 56000 | G37: {=_xlfn.IFS($D$29="Low",'2. Control Panel'!$L$15*'4.1 Revenue & Cost Breakdown'!F132,'4. Financial Projection Summary'!$D$29="Moderate",'2. Control Panel'!$L$16*'4.1 Revenue & Cost Breakdown'!F132,'4. Financial Projection Summary'!$D$29="High",'2. Control Panel'!$L$17*'4.1 Revenue & Cost Breakdown'!F132)} -> 62720 | H37: {=_xlfn.IFS($D$29="Low",'2. Control Panel'!$L$15*'4.1 Revenue & Cost Breakdown'!G132,'4. Financial Projection Summary'!$D$29="Moderate",'2. Control Panel'!$L$16*'4.1 Revenue & Cost Breakdown'!G132,'4. Financial Projection Summary'!$D$29="High",'2. Control Panel'!$L$17*'4.1 Revenue & Cost Breakdown'!G132)} -> 70246.4 | I37: {=_xlfn.IFS($D$29="Low",'2. Control Panel'!$L$15*'4.1 Revenue & Cost Breakdown'!H132,'4. Financial Projection Summary'!$D$29="Moderate",'2. Control Panel'!$L$16*'4.1 Revenue & Cost Breakdown'!H132,'4. Financial Projection Summary'!$D$29="High",'2. Control Panel'!$L$17*'4.1 Revenue & Cost Breakdown'!H132)} -> 78675.968 | J37: {=_xlfn.IFS($D$29="Low",'2. Control Panel'!$L$15*'4.1 Revenue & Cost Breakdown'!I132,'4. Financial Projection Summary'!$D$29="Moderate",'2. Control Panel'!$L$16*'4.1 Revenue & Cost Breakdown'!I132,'4. Financial Projection Summary'!$D$29="High",'2. Control Panel'!$L$17*'4.1 Revenue & Cost Breakdown'!I132)} -> 88117.084 | K37: {=_xlfn.IFS($D$29="Low",'2. Control Panel'!$L$15*'4.1 Revenue & Cost Breakdown'!J132,'4. Financial Projection Summary'!$D$29="Moderate",'2. Control Panel'!$L$16*'4.1 Revenue & Cost Breakdown'!J132,'4. Financial Projection Summary'!$D$29="High",'2. Control Panel'!$L$17*'4.1 Revenue & Cost Breakdown'!J132)} -> 98691.134 | L37: {=_xlfn.IFS($D$29="Low",'2. Control Panel'!$L$15*'4.1 Revenue & Cost Breakdown'!K132,'4. Financial Projection Summary'!$D$29="Moderate",'2. Control Panel'!$L$16*'4.1 Revenue & Cost Breakdown'!K132,'4. Financial Projection Summary'!$D$29="High",'2. Control Panel'!$L$17*'4.1 Revenue & Cost Breakdown'!K132)} -> 110534.07 | ... N37: {=_xlfn.IFS($D$29="Low",'2. Control Panel'!$L$15*'4.1 Revenue & Cost Breakdown'!M132,'4. Financial Projection Summary'!$D$29="Moderate",'2. Control Panel'!$L$16*'4.1 Revenue & Cost Breakdown'!M132,'4. Financial Projection Summary'!$D$29="High",'2. Control Panel'!$L$17*'4.1 Revenue & Cost Breakdown'!M132)} -> 138653.94
D38: OpEx - Totals | E38: =SUM(E34:E37) -> 2655000 | F38: =SUM(F34:F37) -> 2806500 | G38: =SUM(G34:G37) -> 4143770 | H38: =SUM(H34:H37) -> 4433901.4 | I38: =SUM(I34:I37) -> 6644647 | J38: =SUM(J34:J37) -> 7076774.6 | K38: =SUM(K34:K37) -> 7540269.8 | L38: =SUM(L34:L37) -> 8037674.7 | ... N38: =SUM(N34:N37) -> 9145536.8
